[2023-07-15T19:33:24.954+0000] {taskinstance.py:1103} INFO - Dependencies all met for dep_context=non-requeueable deps ti=<TaskInstance: weather_dag.transform_load_weather_data manual__2023-07-15T19:33:14.004083+00:00 [queued]>
[2023-07-15T19:33:24.960+0000] {taskinstance.py:1103} INFO - Dependencies all met for dep_context=requeueable deps ti=<TaskInstance: weather_dag.transform_load_weather_data manual__2023-07-15T19:33:14.004083+00:00 [queued]>
[2023-07-15T19:33:24.961+0000] {taskinstance.py:1308} INFO - Starting attempt 1 of 3
[2023-07-15T19:33:24.977+0000] {taskinstance.py:1327} INFO - Executing <Task(PythonOperator): transform_load_weather_data> on 2023-07-15 19:33:14.004083+00:00
[2023-07-15T19:33:24.983+0000] {standard_task_runner.py:57} INFO - Started process 13241 to run task
[2023-07-15T19:33:24.989+0000] {standard_task_runner.py:84} INFO - Running: ['airflow', 'tasks', 'run', 'weather_dag', 'transform_load_weather_data', 'manual__2023-07-15T19:33:14.004083+00:00', '--job-id', '13', '--raw', '--subdir', 'DAGS_FOLDER/weather_api.py', '--cfg-path', '/tmp/tmpee1ytixc']
[2023-07-15T19:33:24.990+0000] {standard_task_runner.py:85} INFO - Job 13: Subtask transform_load_weather_data
[2023-07-15T19:33:25.027+0000] {task_command.py:410} INFO - Running <TaskInstance: weather_dag.transform_load_weather_data manual__2023-07-15T19:33:14.004083+00:00 [running]> on host ip-172-31-34-181.ap-southeast-1.compute.internal
[2023-07-15T19:33:25.096+0000] {taskinstance.py:1545} INFO - Exporting env vars: AIRFLOW_CTX_DAG_EMAIL='myemail@domain.com' AIRFLOW_CTX_DAG_OWNER='airflow' AIRFLOW_CTX_DAG_ID='weather_dag' AIRFLOW_CTX_TASK_ID='transform_load_weather_data' AIRFLOW_CTX_EXECUTION_DATE='2023-07-15T19:33:14.004083+00:00' AIRFLOW_CTX_TRY_NUMBER='1' AIRFLOW_CTX_DAG_RUN_ID='manual__2023-07-15T19:33:14.004083+00:00'
[2023-07-15T19:33:26.741+0000] {taskinstance.py:1824} ERROR - Task failed with exception
Traceback (most recent call last):
  File "/usr/local/lib/python3.10/dist-packages/s3fs/core.py", line 113, in _error_wrapper
    return await func(*args, **kwargs)
  File "/usr/local/lib/python3.10/dist-packages/aiobotocore/client.py", line 378, in _make_api_call
    raise error_class(parsed_response, operation_name)
botocore.exceptions.ClientError: An error occurred (AccessDenied) when calling the CreateBucket operation: Access Denied

The above exception was the direct cause of the following exception:

Traceback (most recent call last):
  File "/usr/local/lib/python3.10/dist-packages/airflow/operators/python.py", line 181, in execute
    return_value = self.execute_callable()
  File "/usr/local/lib/python3.10/dist-packages/airflow/operators/python.py", line 198, in execute_callable
    return self.python_callable(*self.op_args, **self.op_kwargs)
  File "/home/ubuntu/airflow/dags/weather_api.py", line 62, in transform_load_data
    df_data.to_csv(f"s3://bucketthanh/{dt_string}.csv", index=False, storage_options=aws_credentials)
  File "/usr/local/lib/python3.10/dist-packages/pandas/core/generic.py", line 3772, in to_csv
    return DataFrameRenderer(formatter).to_csv(
  File "/usr/local/lib/python3.10/dist-packages/pandas/io/formats/format.py", line 1186, in to_csv
    csv_formatter.save()
  File "/usr/local/lib/python3.10/dist-packages/pandas/io/formats/csvs.py", line 240, in save
    with get_handle(
  File "/usr/local/lib/python3.10/dist-packages/pandas/io/common.py", line 716, in get_handle
    ioargs = _get_filepath_or_buffer(
  File "/usr/local/lib/python3.10/dist-packages/pandas/io/common.py", line 425, in _get_filepath_or_buffer
    file_obj = fsspec.open(
  File "/usr/local/lib/python3.10/dist-packages/fsspec/core.py", line 439, in open
    out = open_files(
  File "/usr/local/lib/python3.10/dist-packages/fsspec/core.py", line 293, in open_files
    [fs.makedirs(parent, exist_ok=True) for parent in parents]
  File "/usr/local/lib/python3.10/dist-packages/fsspec/core.py", line 293, in <listcomp>
    [fs.makedirs(parent, exist_ok=True) for parent in parents]
  File "/usr/local/lib/python3.10/dist-packages/fsspec/asyn.py", line 121, in wrapper
    return sync(self.loop, func, *args, **kwargs)
  File "/usr/local/lib/python3.10/dist-packages/fsspec/asyn.py", line 106, in sync
    raise return_result
  File "/usr/local/lib/python3.10/dist-packages/fsspec/asyn.py", line 61, in _runner
    result[0] = await coro
  File "/usr/local/lib/python3.10/dist-packages/s3fs/core.py", line 892, in _makedirs
    await self._mkdir(path, create_parents=True)
  File "/usr/local/lib/python3.10/dist-packages/s3fs/core.py", line 877, in _mkdir
    await self._call_s3("create_bucket", **params)
  File "/usr/local/lib/python3.10/dist-packages/s3fs/core.py", line 348, in _call_s3
    return await _error_wrapper(
  File "/usr/local/lib/python3.10/dist-packages/s3fs/core.py", line 140, in _error_wrapper
    raise err
PermissionError: Access Denied
[2023-07-15T19:33:26.758+0000] {taskinstance.py:1345} INFO - Marking task as UP_FOR_RETRY. dag_id=weather_dag, task_id=transform_load_weather_data, execution_date=20230715T193314, start_date=20230715T193324, end_date=20230715T193326
[2023-07-15T19:33:26.773+0000] {standard_task_runner.py:104} ERROR - Failed to execute job 13 for task transform_load_weather_data (Access Denied; 13241)
[2023-07-15T19:33:26.807+0000] {local_task_job_runner.py:225} INFO - Task exited with return code 1
[2023-07-15T19:33:26.819+0000] {taskinstance.py:2653} INFO - 0 downstream tasks scheduled from follow-on schedule check
